<?xml version="1.0" encoding="utf-8"?>
<!-- =================================================================================== -->
<!-- |    This document was autogenerated by xacro from URDF_armv001.urdf              | -->
<!-- |    EDITING THIS FILE BY HAND IS NOT RECOMMENDED                                 | -->
<!-- =================================================================================== -->
<!-- This URDF was automatically created by SolidWorks to URDF Exporter! Originally created by Stephen Brawner (brawner@gmail.com) 
     Commit Version: 1.6.0-4-g7f85cfe  Build Version: 1.6.7995.38578
     For more information, please see http://wiki.ros.org/sw_urdf_exporter -->
<robot xmlns:xacro="http://www.ros.org/wiki/xacro" name="URDF_armv001">
  <link name="base_link">
    <inertial>
      <origin rpy="0 0 0" xyz="0.00012503 1.4745E-05 0.026752"/>
      <mass value="0.0000181"/>
      <inertia ixx="55.145" ixy="1.5556E-06" ixz="1.4779E-06" iyy="103.27" iyz="8.2802E-08" izz="146.16"/>
    </inertial>
    <visual>
      <origin rpy="0 0 0" xyz="0 0 0"/>
      <geometry>
        <mesh filename="package://URDF_armv001/meshes/base_link.STL"/>
      </geometry>
      <material name="">
        <color rgba="0 0.94118 0.98824 1"/>
      </material>
    </visual>
    <collision>
      <origin rpy="0 0 0" xyz="0 0 0"/>
      <geometry>
        <mesh filename="package://URDF_armv001/meshes/base_link.STL"/>
      </geometry>
    </collision>
  </link>
  <link name="first_Link">
    <inertial>
      <origin rpy="0 0 0" xyz="0.0019709 -3.7688E-05 0.045814"/>
      <mass value="0.0000105"/>
      <inertia ixx="20.197" ixy="-1.66E-08" ixz="2.2663E-07" iyy="11.25" iyz="7.8462E-08" izz="14.31"/>
    </inertial>
    <visual>
      <origin rpy="0 0 0" xyz="0 0 0"/>
      <geometry>
        <mesh filename="package://URDF_armv001/meshes/first_Link.STL"/>
      </geometry>
      <material name="">
        <color rgba="0.79216 0.81961 0.93333 1"/>
      </material>
    </visual>
    <collision>
      <origin rpy="0 0 0" xyz="0 0 0"/>
      <geometry>
        <mesh filename="package://URDF_armv001/meshes/first_Link.STL"/>
      </geometry>
    </collision>
  </link>
  <joint name="first_joint" type="revolute">
    <origin rpy="0 0 0" xyz="0 0 0.0785000000000001"/>
    <parent link="base_link"/>
    <child link="first_Link"/>
    <axis xyz="0 0 1"/>
    <limit effort="160" lower="-3.14" upper="3.14" velocity="20.417"/>
  </joint>
  <link name="second_Link">
    <inertial>
      <origin rpy="0 0 0" xyz="0.000857573444558835 0.0776042459103315 0.130616624503666"/>
      <mass value="0.00000966"/>
      <inertia ixx="246.169175712987" ixy="7.15160471159471E-06" ixz="1.14970999493612E-05" iyy="149.301141014258" iyz="-0.00107551298210178" izz="101.59642390867"/>
    </inertial>
    <visual>
      <origin rpy="0 0 0" xyz="0 0 0"/>
      <geometry>
        <mesh filename="package://URDF_armv001/meshes/second_Link.STL"/>
      </geometry>
      <material name="">
        <color rgba="0 0.941176470588235 0.988235294117647 1"/>
      </material>
    </visual>
    <collision>
      <origin rpy="0 0 0" xyz="0 0 0"/>
      <geometry>
        <mesh filename="package://URDF_armv001/meshes/second_Link.STL"/>
      </geometry>
    </collision>
  </link>
  <joint name="second_joint" type="revolute">
    <origin rpy="0 0 0" xyz="0 0 0.0614999999999968"/>
    <parent link="first_Link"/>
    <child link="second_Link"/>
    <axis xyz="-1 0 0"/>
    <limit effort="60" lower="-2.15" upper="1.26" velocity="20.4165"/>
  </joint>
  <link name="third_Link">
    <inertial>
      <origin rpy="0 0 0" xyz="0.00167558365991412 -0.116252462462107 0.0252492816668452"/>
      <mass value="0.0000069"/>
      <inertia ixx="58.2679607750313" ixy="-1.4662142928383E-05" ixz="1.94509615851066E-06" iyy="7.33395566734886" iyz="4.46085226928446E-05" izz="55.3919549010076"/>
    </inertial>
    <visual>
      <origin rpy="0 0 0" xyz="0 0 0"/>
      <geometry>
        <mesh filename="package://URDF_armv001/meshes/third_Link.STL"/>
      </geometry>
      <material name="">
        <color rgba="0 0.941176470588235 0.988235294117647 1"/>
      </material>
    </visual>
    <collision>
      <origin rpy="0 0 0" xyz="0 0 0"/>
      <geometry>
        <mesh filename="package://URDF_armv001/meshes/third_Link.STL"/>
      </geometry>
    </collision>
  </link>
  <joint name="third_joint" type="revolute">
    <origin rpy="0 0 0" xyz="0 0.165989898732231 0.257913780286487"/>
    <parent link="second_Link"/>
    <child link="third_Link"/>
    <axis xyz="-1 0 0"/>
    <limit effort="17" lower="-0.75" upper="2.38" velocity="32.9805"/>
  </joint>
  <link name="fourth_Link">
    <inertial>
      <origin rpy="0 0 0" xyz="3.0956E-05 -0.027807 -7.0032E-05"/>
      <mass value="0.0000037"/>
      <inertia ixx="3.2899" ixy="2.5288E-06" ixz="-2.3777E-08" iyy="2.1257" iyz="1.4904E-07" izz="2.1529"/>
    </inertial>
    <visual>
      <origin rpy="0 0 0" xyz="0 0 0"/>
      <geometry>
        <mesh filename="package://URDF_armv001/meshes/fourth_Link.STL"/>
      </geometry>
      <material name="">
        <color rgba="0 0.94118 0.98824 1"/>
      </material>
    </visual>
    <collision>
      <origin rpy="0 0 0" xyz="0 0 0"/>
      <geometry>
        <mesh filename="package://URDF_armv001/meshes/fourth_Link.STL"/>
      </geometry>
    </collision>
  </link>
  <joint name="fourth_joint" type="revolute">
    <origin rpy="0 0 0" xyz="0 -0.247999999999997 0.0289999999999987"/>
    <parent link="third_Link"/>
    <child link="fourth_Link"/>
    <axis xyz="0 1 0"/>
    <limit effort="14" lower="-3.14" upper="3.14" velocity="32.9805"/>
  </joint>
  <link name="fifth_Link">
    <inertial>
      <origin rpy="0 0 0" xyz="0.00300098384037063 -0.0489667534520629 -0.00025041259776476"/>
      <mass value="0.0000037"/>
      <inertia ixx="2071.64941375216" ixy="-3.06195815006198E-06" ixz="-5.10277075875545E-08" iyy="3104.81600066296" iyz="9.30254252584598E-08" izz="2271.19764110177"/>
    </inertial>
    <visual>
      <origin rpy="0 0 0" xyz="0 0 0"/>
      <geometry>
        <mesh filename="package://URDF_armv001/meshes/fifth_Link.STL"/>
      </geometry>
      <material name="">
        <color rgba="0.317647058823529 0.635294117647059 1 1"/>
      </material>
    </visual>
    <collision>
      <origin rpy="0 0 0" xyz="0 0 0"/>
      <geometry>
        <mesh filename="package://URDF_armv001/meshes/fifth_Link.STL"/>
      </geometry>
    </collision>
  </link>
  <joint name="fifth_joint" type="revolute">
    <origin rpy="0 0 0" xyz="0 -0.036 0"/>
    <parent link="fourth_Link"/>
    <child link="fifth_Link"/>
    <axis xyz="-1 0 0"/>
    <limit effort="14" lower="-1.57" upper="1.57" velocity="32.9805"/>
  </joint>
  <link name="sixth_Link">
    <inertial>
      <origin rpy="0 0 0" xyz="1.39012723646137E-06 -0.0549727115442942 -0.000135720167939724"/>
      <mass value="0.000005"/>
      <inertia ixx="3561.33730917755" ixy="4.25963069298585E-09" ixz="7.55175416452852E-09" iyy="16234.2067218402" iyz="9.33294369793947E-08" izz="16156.1054644543"/>
    </inertial>
    <visual>
      <origin rpy="0 0 0" xyz="0 0 0"/>
      <geometry>
        <mesh filename="package://URDF_armv001/meshes/sixth_Link.STL"/>
      </geometry>
      <material name="">
        <color rgba="0.792156862745098 0.819607843137255 0.933333333333333 1"/>
      </material>
    </visual>
    <collision>
      <origin rpy="0 0 0" xyz="0 0 0"/>
      <geometry>
        <mesh filename="package://URDF_armv001/meshes/sixth_Link.STL"/>
      </geometry>
    </collision>
  </link>
  <joint name="sixth_joint" type="revolute">
    <origin rpy="0 0 0" xyz="-0.00100000000000486 -0.0869999999999949 0"/>
    <parent link="fifth_Link"/>
    <child link="sixth_Link"/>
    <axis xyz="0 1 0"/>
    <limit effort="14" lower="-3.14" upper="3.14" velocity="32.9805"/>
  </joint>

  <xacro:macro name="transmission_block" params="joint_name">
    <transmission name="${joint_name}_tran">
      <type>transmission_interface/SimpleTransmission</type>
      <joint name="${joint_name}">
        <hardwareInterface>hardware_interface/PositionJointInterface</hardwareInterface>
      </joint>
      <actuator name="${joint_name}_motor">
        <hardwareInterface>hardware_interface/PositionJointInterface</hardwareInterface>
        <mechanicalReduction>1</mechanicalReduction>
      </actuator>
    </transmission>
  </xacro:macro>
  
  <xacro:transmission_block joint_name="first_joint"/>
  <xacro:transmission_block joint_name="second_joint"/>
  <xacro:transmission_block joint_name="third_joint"/>
  <xacro:transmission_block joint_name="fourth_joint"/>
  <xacro:transmission_block joint_name="fifth_joint"/>
  <xacro:transmission_block joint_name="sixth_joint"/>

  <gazebo>
    <plugin name="gazebo_ros_control" filename="libgazebo_ros_control.so">
      <robotNamespace>/URDF_armv001</robotNamespace>
      <robotSimType>gazebo_ros_control/DefaultRobotHWSim</robotSimType>
      <legacyModeNS>true</legacyModeNS>
    </plugin>
  </gazebo>
</robot>


